Workbook

Sheet READ ME
A1: kim23-lab-index HPメタデータ（labratory_ktech記事）
A3: note.com「Kim23 Test Laboratory」全293記事のメタデータです。
A4: 本サイトの content/articles/*.md フロントマター（src/content.config.ts のスキーマ）に対応する形式で整理しています。
A6: ① 記事メタデータ
A7: title / car / ecu / purpose / note_url / related / date は content.config.ts のフィールド名と一致。
A8: slug列は content/articles/{slug}.md として保存する際のファイル名（拡張子なし）候補です。
A9: related列は関連記事のslugをカンマ区切りで格納（同一車種内のSTEP前後関係を自動リンク）。
A10: このシートの1行がそのまま1記事のフロントマターの元データになります。
A12: ② 車種展開_Pivot用
A13: 1記事が複数車種に該当する場合は行を複製し、1行=1記事×1車種に正規化。
A14: Excelで選択→挿入→ピボットテーブル、で車種・カテゴリ・ECU等を自由に集計・分析できます。
A16: ③ 車種×カテゴリ集計
... A26: データ取得日: 2026-09-12 / 出典: https://note.com/labratory_ktech

Sheet 記事メタデータ
A1: slug | B1: title | C1: car | D1: ecu | E1: purpose | F1: note_url | G1: related | H1: date | I1: category | J1: step | K1: magazines | L1: tags | M1: price
A2: misc-84a7b3 | B2: 初めましてなのか、お久しぶりなのか？ | C2: （共通・車種特定なし） | E2: 初めましての方は初めまして！ お久しぶり？の方はお久しぶりです。 | F2: https://note.com/labratory_ktech/n/nf4258784a7b3 | H2: 2025-02-18 | I2: その他 | K2: （未分類） | L2: #情報 #データ #ノウハウ #伝承 #ECU #ECUチューニング | M2: 0
A3: misc-linkecu-e865c2 | B3: 自動車 フルコン化に必要なモノ | C3: （共通・車種特定なし） | D3: LINKECU | E3: まず、この記事をベースにこの後のフルコン化の記事を読んで貰いたい対象者を設定しますね(´・ω・｀) 対象者 ・自分の車を LINKECU、M… | F3: https://note.com/labratory_ktech/n/n192a1be865c2 | H3: 2025-02-20 | I3: 基礎知識・準備 | K3: ECUフルコン化への道 | L3: #フルコン #ECU #LINKECU #ECUチューニング #安定化電源 | M3: 0
A4: misc-228e07 | B4: 安定化電源を使う理由 | C4: （共通・車種特定なし） | E4: 電気系のテストをするのに安定化電源が必要だと言ったのですが、その観点を説明します。 | F4: https://note.com/labratory_ktech/n/nfe3377228e07 | H4: 2025-02-23 | I4: 基礎知識・準備 | K4: ECUフルコン化への道 | L4: #テスト #バッテリー #電源 #電圧 #安定化電源 | M4: 0
A5: misc-linkecu-6aecda | B5: フルコン勉強にお勧めのECUは？ | C5: （共通・車種特定なし） | D5: LINKECU/MaxxECU/MOTEC/EMTRON/Haltech | E5: ECUフルコン化をやってみようー！ と、思ったときにどのECUを選ぶか悩むと思います。 | F5: https://note.com/labratory_ktech/n/n9881036aecda | H5: 2025-02-24 | I5: 基礎知識・準備 | K5: ECUフルコン化への道 | L5: #機能 #セッティング #フルコン #ECU #LINKECU #ecuセッティング #MaxxECU #MoTeC #Haltech #EMTRON | M5: 0
A6: misc-linkecu-160fa8 | B6: 燃料セッティング 空燃比計とは？ | C6: （共通・車種特定なし） | D6: LINKECU | E6: 始めにECUフルコンのセッティングやるのに空燃比計センサー付けないといけないんでしょ？って思っている人！ 空燃比計買う前に、ちょっと待ってく… | F6: https://note.com/labratory_ktech/n/n182b31160fa8 | H6: 2025-02-26 | I6: 基礎知識・準備 | K6: ECUフルコン化への道 | L6: #アナログ #CAN #フルコン #ECU #LINKECU #空燃比計 | M6: 0
A7: misc-linkecu-711682 | B7: 初心者？がECUフルコンを選定するのに一番大事なこと | C7: （共通・車種特定なし） | D7: LINKECU/MaxxECU | E7: 以前にお勧めのECUがLINKECUとMaxxECUだと推奨しました。 | F7: https://note.com/labratory_ktech/n/n612e8f711682 | H7: 2025-02-27 | I7: 基礎知識・準備 | K7: ECUフルコン化への道 | L7: #設定 #信号 #フルコン #LINKECU #MaxxECU #TRIGGER設定 | M7: 0
A8: misc-linkecu-275a47 | B8: LINKECU MAXXECU どの機種選べばいいの？ | C8: （共通・車種特定なし） | D8: LINKECU/MaxxECU | E8: フルコンこれから始める人にはLINKECUか MAXXECUをお勧めしていました。 | F8: https://note.com/labratory_ktech/n/n5515d1275a47 | H8: 2025-03-01 | I8: 他社ECU・機器情報 | K8: LINKECU 関連/MaxxECU フルコン化への道/ECUフルコン化への道 | L8: #フルコン #LINKECU #車いじり #ECUチューニング #MaxxECU | M8: 0
A9: esse-cc2978 | B9: フルコン化の第１の壁 吸気圧力センサ特性どうやって測定するの？ | C9: エッセ(ESSE) | E9: フルコン化が一般的にされている車両の場合は、吸気圧力センサの特性がソフトウェアのプルダウンで選べるのですが、プルダウンで選べない場合、センサ… | F9: https://note.com/labratory_ktech/n/n4fe44ccc2978 | H9: 2025-03-02 | I9: センサ・計測データ | K9: エッセ ESSE LINKECU フルコン化 への道/ECUフルコン化への道/吸気圧力センサ 電圧-圧力特性測定結果 | L9: #データ #圧力 #センサ #MAPセンサ #吸気圧力センサ #PressureSensor | M9: 0
A10: fd3s-linkecu-774f15 | B10: LINKECU PLUG IN FD3S 後期 電源供給 | C10: FD3S(RX-7) | D10: LINKECU | E10: FD3Sプラグインに対して電源供給する方法を紹介します UNBOXカバースライドさせます 開けると基盤が入ってます 袋から出してUSBケーブ… | F10: https://note.com/labratory_ktech/n/n4a4ba4774f15 | H10: 2025-03-03 | I10: 基礎知識・準備 | K10: LINKECU 関連/ECUフルコン化への道/FD3S LINKECU フルコン化への道 | L10: #セッティング #ECU #LINKECU #フルコン化 #PCLINK #電圧供給 #FD3S後期 | M10: 0
A11: ae86-linkecu-460ba3 | B11: AE86 4AG 吸気圧力センサ特性 品番89421-12020 | C11: AE86 | D11: LINKECU/MaxxECU | E11: 以下注意事項測定データは、あるセンサにおいて、n=1～5のデータによるもの、測定誤差、サンプル誤差などを含んだものです。 | F11: https://note.com/labratory_ktech/n/n3b3112460ba3 | H11: 2025-03-03 | I11: センサ・計測データ | K11: 吸気圧力センサ 電圧-圧力特性測定結果 | L11: #AE86 #実験結果 #LINKECU #測定結果 #MaxxECU #圧力センサ #MAPセンサ #吸気圧力センサ #4AG | M11: 2000
A12: misc-linkecu-16c728 | B12: LINKECU 通電 と アンロック作業 | C12: （共通・車種特定なし） | D12: LINKECU | E12: LINKECUを動かすにはアンロック作業なるものが必要になります。 | F12: https://note.com/labratory_ktech/n/n4a2c4616c728 | H12: 2025-03-03 | I12: 基礎知識・準備 | K12: ECUフルコン化への道 | L12: #ソフトウェア #ECU #アンロック #LINKECU #フルコン化 #安定化電源 | M12: 0
A13: misc-8b7628 | B13: AE92 4AG 吸気圧力センサ特性 品番 80420-20300 | C13: （共通・車種特定なし） | E13: 以下注意事項 測定データは、あるセンサにおいて、n=1～5のデータによるもの、測定誤差、サンプル誤差などを含んだものです。 | F13: https://note.com/labratory_ktech/n/nee83a58b7628 | H13: 2025-03-04 | I13: センサ・計測データ | K13: 吸気圧力センサ 電圧-圧力特性測定結果 | L13: #データ #校正 #測定結果 #圧力センサ #AE92 #吸気圧力センサ #電圧圧力 | M13: 2000
A14: misc-2b1b60 | B14: フルコン化への道 ビギーバック配線とは？ | C14: （共通・車種特定なし） | E14: ビギーバックとは？Piggyback（ピギーバック）とは、もともと「背負う」「おんぶする」という意味の英語です。 | F14: https://note.com/labratory_ktech/n/n4a159e2b1b60 | H14: 2025-03-05 | I14: 基礎知識・準備 | K14: ECUフルコン化への道 | L14: #配線 #フルコン #ECU #ECUチューニング #ビギーバック | M14: 0
A15: altoworks-step0-4670ac | B15: HA22Sフルコン化 STEP0 ECUピンアサイン | C15: アルトワークス(HA22S/HA23S) | E15: 純正ECUをフルコン化する際に、まずはじめに純正のピンアサインを把握する必要があります。 | F15: https://note.com/labratory_ktech/n/na152494670ac | G15: altoworks-linkecu-step1-362693 | H15: 2025-03-08 | I15: STEP本編（フルコン化手順） | J15: STEP0 | K15: 新規格 K6A フルコン化情報/アルトワークス フルコン化 HA22S事例 | L15: #ダウンロード #純正 #フルコン #Step0 #ECUピンアサイン #HA22Sフルコン化 | M15: 500
A16: altoworks-linkecu-step1-362693 | B16: HA22S K6A フルコン化 STEP1 ビギーバックハーネス | C16: アルトワークス(HA22S/HA23S) | D16: LINKECU | E16: ビギーバックハーネスとは？ビギーバックハーネスは何か？使用をお勧めする理由を、以下の記事で記載しています。 | F16: https://note.com/labratory_ktech/n/ne2f733362693 | G16: altoworks-linkecu-step2-e48ff8, altoworks-step0-4670ac | H16: 2025-03-08 | I16: STEP本編（フルコン化手順） | J16: STEP1 | K16: アルトワークス フルコン化 HA22S事例 | L16: #配線 #LINKECU #フルコン化 #アルトワークス #HA22S #K6A #ビギーバックハーネス #ECU延長ハーネス | M16: 0
A17: altoworks-linkecu-f776fe | B17: HA22S K6A アルトワークスフルコン化 | C17: アルトワークス(HA22S/HA23S) | D17: LINKECU | E17: ECUフルコン化の内容を紹介しようとしていましたが、ベースとなる車両やエンジンを何にしようとかと悩んでいました。 | F17: https://note.com/labratory_ktech/n/n3eb953f776fe | H17: 2025-03-08 | I17: 基礎知識・準備（車種別） | K17: アルトワークス フルコン化 HA22S事例 | L17: #フルコン #LINKECU #ECUチューニング #アルトワークス #HA22S #K6A | M17: 0
A18: cappuccino-linkecu-e16ea7 | B18: F6A アルトカプチーノ 吸気圧力センサ特性 品番 18590-64D00 | C18: カプチーノ(F6A) | D18: LINKECU | E18: 以下注意事項 測定データは、あるセンサにおいて、n=1～5のデータによるもの、測定誤差、サンプル誤差などを含んだものです。 | F18: https://note.com/labratory_ktech/n/neaa561e16ea7 | H18: 2025-03-08 | I18: センサ・計測データ | K18: 吸気圧力センサ 電圧-圧力特性測定結果 | L18: #データ #センサー #実験結果 #LINKECU #ECUチューニング #F6A #圧力センサ特性 | M18: 3000
A19: misc-2668a9 | B19: インジェクター燃料圧力制御の基礎 燃料のリターン、リターンレスシステムとは？ | C19: （共通・車種特定なし） | E19: エンジンの出力UPを行う、ECUセッティングをするのに燃料圧力の制御方法の理解が必要だと思います。 | F19: https://note.com/labratory_ktech/n/n0f32362668a9 | H19: 2025-03-08 | I19: センサ・計測データ | K19: 燃料、インジェクター関連 無効噴射時間 | L19: #燃料 #ECUチューニング #ecuセッティング #インジェクター #燃圧 #吸気圧力 #燃料噴射量 | M19: 0
A20: altoworks-linkecu-step2-e48ff8 | B20: HA22S LINKECU フルコン化 STEP2 電源供給 | C20: アルトワークス(HA22S/HA23S) | D20: LINKECU | E20: HA22Sの車両とECU間にビギーバックハーネスがある前提で進めます。 | F20: https://note.com/labratory_ktech/n/n3bb503e48ff8 | G20: altoworks-linkecu-step1-362693, altoworks-linkecu-step3-ff1549 | H20: 2025-03-09 | I20: STEP本編（フルコン化手順） | J20: STEP2 | K20: アルトワークス フルコン化 HA22S事例/ECUフルコン化への道 | L20: #電源 #配線 #LINKECU #フルコン化 #HA22S #K6A #ビギーバック | M20: 0
A21: altoworks-b01abe | B21: 温度センサ校正の基礎知識 分圧とは？ | C21: アルトワークス(HA22S/HA23S) | E21: エンジンの水温センサ吸気温度センサ等のサーミスタを用いた抵抗変化による温度計測をするのに、分圧の知識は絶対に必要になります。 | F21: https://note.com/labratory_ktech/n/ne58f6db01abe | H21: 2025-03-10 | I21: 基礎知識・準備 | K21: アルトワークス フルコン化 HA22S事例/ECUフルコン化への道 | L21: #抵抗 #電圧 #オームの法則 #温度センサ #分圧 #センサ校正 | M21: 0
A22: altoworks-linkecu-step3-ff1549 | B22: HA22S フルコン化 STEP3 スロットル信号入力とアナログ入力エラー設定の観点 | C22: アルトワークス(HA22S/HA23S) | D22: LINKECU | E22: おさらいSTEP2では電源が入るところまで確認しました。 | F22: https://note.com/labratory_ktech/n/n58a1cbff1549 | G22: altoworks-linkecu-step2-e48ff8, altoworks-linkecu-step4-ceb9fa | H22: 2025-03-11 | I22: STEP本編（フルコン化手順） | J22: STEP3 | K22: アルトワークス フルコン化 HA22S事例/ECUフルコン化への道 | L22: #設定 #配線 #LINKECU #ECUチューニング #フルコン化 #スロットル #開度信号 | M22: 100
A23: altoworks-075bb5 | B23: HA22 温度センサー 温度-抵抗特性測定結果 | C23: アルトワークス(HA22S/HA23S) | E23: 温度センサの特性を測定する方法を紹介しました。 | F23: https://note.com/labratory_ktech/n/n6cea0c075bb5 | H23: 2025-03-13 | I23: 部品選定・レビュー | K23: アルトワークス フルコン化 HA22S事例/HA22S 部品関連情報/温度センサ関連 | M23: 500
A24: misc-a2b1f2 | B24: 温度センサの温度-抵抗特性 と B定数 | C24: （共通・車種特定なし） | E24: 自動車用に使われている温度センサとは？自動車のエンジン制御で使われる、水温センサや吸気温度センサは、サーミスタ (Thermistor)TYPEがほとんどです。 | F24: https://note.com/labratory_ktech/n/nf904daa2b1f2 | H24: 2025-03-13 | I24: センサ・計測データ | K24: LINKECU 関連/温度センサ関連/ECUフルコン化への道 | L24: #温度 #センサ #ECUチューニング #抵抗値 #温度センサー #水温センサー #吸気温度センサー #B定数 | M24: 0
A25: copen-linkecu-6815ae | B25: JB-DET コペン 吸気圧力センサ 品番 89421-97201 特性測定結果 | C25: コペン(L880K) | D25: LINKECU | E25: 以下注意事項 測定データは、あるセンサにおいて、n=1のデータによるもの、測定誤差、サンプル誤差などを含んだものです。 | F25: https://note.com/labratory_ktech/n/nd325a66815ae | H25: 2025-03-14 | I25: センサ・計測データ | K25: 吸気圧力センサ 電圧-圧力特性測定結果/コペン L880K フルコン化 | L25: #コペン #l880k #LINKECU #ECUチューニング #フルコン化 #圧力センサ #吸気圧力センサ #圧力センサ特性 | M25: 2000
A26: altoworks-linkecu-91bebe | B26: HA22S 吸気圧力センサ HITACHI製 品番 18590-78G50 特性測定結果 | C26: アルトワークス(HA22S/HA23S) | D26: LINKECU | E26: 以下注意事項 測定データは、あるセンサにおいて、n=1～5程度のデータによるもの、測定誤差、サンプル誤差などを含んだものです。 | F26: https://note.com/labratory_ktech/n/n6cfee691bebe | H26: 2025-03-15 | I26: センサ・計測データ | K26: アルトワークス フルコン化 HA22S事例/吸気圧力センサ 電圧-圧力特性測定結果 | L26: #フルコン #LINKECU #ECUチューニング #フルコン化 #アルトワークス #K6A #圧力センサー #MAPセンサ #確認結果 | M26: 2000
A27: altoworks-linkecu-step4-ceb9fa | B27: HA22S フルコン化 STEP4 吸気圧力信号入力 と センサCaliblation設定の観点 | C27: アルトワークス(HA22S/HA23S) | D27: LINKECU | E27: おさらいSTEP3ではスロットルポジションセンサの動作を確認しました。 | F27: https://note.com/labratory_ktech/n/nb5f07fceb9fa | G27: altoworks-linkecu-step3-ff1549, altoworks-linkecu-step5-e41aba | H27: 2025-03-16 | I27: STEP本編（フルコン化手順） | J27: STEP4 | K27: アルトワークス フルコン化 HA22S事例/ECUフルコン化への道 | L27: #LINKECU #フルコン化 #HA22S #K6A #LINKECUセッティング #圧力センサ #MAPセンサ #吸気圧力センサ | M27: 0
A28: altoworks-linkecu-b980ee | B28: HA23 吸気圧力センサ Denso製 品番 18590-79F00 特性測定結果 | C28: アルトワークス(HA22S/HA23S) | D28: LINKECU | E28: HA23等は、スロットルボディが流用されている、別の車種のエンジンが使用されている場合があります。 | F28: https://note.com/labratory_ktech/n/n0c63cbb980ee | H28: 2025-03-16 | I28: その他 | K28: （未分類） | L28: #データ #アルト #センサ #実験結果 #LINKECU #ECUチューニング #K6A #MAPセンサ #吸気圧力センサ #HA23 | M28: 2000
A29: misc-26b3d3 | B29: 燃料圧力と噴射量の関係性 | C29: （共通・車種特定なし） | E29: 燃料圧力と噴射量の関係は、ベルヌーイの定理と流体力学の基本原理を使って説明できます。 | F29: https://note.com/labratory_ktech/n/n57277926b3d3 | H29: 2025-03-17 | I29: センサ・計測データ | K29: 燃料、インジェクター関連 無効噴射時間/ECUフルコン化への道 | L29: #燃料 #平方根 #インジェクター #燃圧 #燃料圧力 #燃料圧力レギュレーター #噴射量 | M29: 0
A30: misc-bb3fb4 | B30: インジェクタ流量と馬力の関係 | C30: （共通・車種特定なし） | E30: 過去に自分が6気筒エンジンで1000ｃｃ/minインジェクターのDutyが85％だから、800馬力くらい出たかなー？ 等とつぶやくことがあっ… | F30: https://note.com/labratory_ktech/n/n5809cebb3fb4 | H30: 2025-03-18 | I30: センサ・計測データ | K30: 燃料、インジェクター関連 無効噴射時間/ECUフルコン化への道 | L30: #hp #馬力 #フルコン化 #ecuセッティング #Duty #インジェクター #馬力計算 #インジェクター噴射量 | M30: 200
A31: misc-linkecu-922d25 | B31: TA-HE21S ラパンSS 純正ECUピンアサイン エクセルファイル | C31: （共通・車種特定なし） | D31: LINKECU | E31: HA22S後期アルトワークスを事例にフルコン化作業を紹介しています。 | F31: https://note.com/labratory_ktech/n/n959df6922d25 | H31: 2025-03-19 | I31: 配線・ピンアサイン資料 | K31: 新規格 K6A フルコン化情報 | L31: #ダウンロード #整備書 #ラパン #フルコン化 #K6A #LINKECUセッティング #HE21S #ラパンSS #新規格K6A #純正ECU #ECUピンアサイン #TAHE21S | M31: 5000
A32: misc-6a1297 | B32: HN12等 F6A ターボ 吸気圧力センサ Denso製 品番 18590-76G50 特性測定結果 | C32: （共通・車種特定なし） | E32: スズキの車両は、スロットルボディが流用されている、別の車種のエンジンが使用されている場合があります。 | F32: https://note.com/labratory_ktech/n/n3cf1366a1297 | H32: 2025-03-21 | I32: センサ・計測データ | K32: 吸気圧力センサ 電圧-圧力特性測定結果 | L32: #データ #Kei #センサ #実験結果 #フルコン化 #ecuセッティング #フルコンセッティング #MAPセンサ #吸気圧力センサ #F6A #電圧圧力特性 #圧力センサ校正 | M32: 2000
A33: misc-motec-4c23e9 | B33: GM MAP SENSOR | C33: （共通・車種特定なし） | D33: MOTEC | E33: ECUフルコン化に必要な情報がすべて手に入る場所を作りたいと思い、Noteを書いています。 | F33: https://note.com/labratory_ktech/n/n966de44c23e9 | H33: 2025-03-21 | I33: センサ・計測データ | K33: 吸気圧力センサ 電圧-圧力特性測定結果 | L33: #Gm #センサ #フルコン化 #ecuセッティング #MoTeC #MAPセンサ #電圧圧力特性 #MAPSENSOR #GM1BAR #GM2BAR #GM3BAR | M33: 0
A34: misc-linkecu-733713 | B34: 温度センサ校正の基礎 LINKECU例 プルアップ抵抗 有り編 | C34: （共通・車種特定なし） | D34: LINKECU | E34: ふりかえり先ずは以下の記事を見て分圧の内容を理解しておいてください。 | F34: https://note.com/labratory_ktech/n/n8e1736733713 | H34: 2025-03-23 | I34: センサ・計測データ | K34: LINKECU 関連/温度センサ関連 | L34: #温度 #抵抗 #LINKECU #フルコン化 #ecuセッティング #プルアップ #LINKECUセッティング #温度センサ校正 #温度校正 | M34: 0
A35: misc-linkecu-451883 | B35: 温度センサ校正の基礎 LINKECU例 プルアップ抵抗OFF ビギーバック編 | C35: （共通・車種特定なし） | D35: LINKECU | E35: ふりかえりプルアップ抵抗有り時の、温度校正設定の概要を説明しました。 | F35: https://note.com/labratory_ktech/n/n0085d3451883 | H35: 2025-03-25 | I35: センサ・計測データ | K35: LINKECU 関連/温度センサ関連/ECUフルコン化への道 | L35: #抵抗 #LINKECU #フルコン化 #ecuセッティング #プルアップ #ビギーバック #温度センサ #プルアップ抵抗 #温度センサ校正 #ビギーバック配線 | M35: 500
A36: misc-linkecu-1d2d43 | B36: SARD1000cc/min 低抵抗 インジェクター | C36: （共通・車種特定なし） | D36: LINKECU | F36: https://note.com/labratory_ktech/n/nfb525f1d2d43 | H36: 2025-03-27 | I36: 部品選定・レビュー | K36: 車関係部品 写真置き場 | L36: #燃料 #LINKECU #フルコン化 #ecuセッティング #インジェクター | M36: 0
A37: misc-linkecu-660efd | B37: 1JZ 2JZ 等 ターボ用 吸気圧力センサ Denso製 品番 89421-12111 特性測定結果 | C37: （共通・車種特定なし） | D37: LINKECU | E37: エンジンに対して純正とは違う吸気圧力センサが取り付けられている可能性があります。 | F37: https://note.com/labratory_ktech/n/n9b53de660efd | H37: 2025-03-29 | I37: センサ・計測データ | K37: 吸気圧力センサ 電圧-圧力特性測定結果 | L37: #データ #センサ #実験結果 #LINKECU #LINKECUセッティング #1jz #圧力センサ #2JZ #MAPセンサ #圧力センサ校正 | M37: 2000
A38: altoworks-linkecu-step5-e41aba | B38: HA22S フルコン化 STEP5 温度センサ校正設定 | C38: アルトワークス(HA22S/HA23S) | D38: LINKECU | E38: おさらいSTEP4ではスロットルポジションセンサの動作を確認しました。 | F38: https://note.com/labratory_ktech/n/ne1c5b4e41aba | G38: altoworks-linkecu-step4-ceb9fa, altoworks-step5-2-865d7b | H38: 2025-03-29 | I38: STEP本編（フルコン化手順） | J38: STEP5 | K38: 新規格 K6A フルコン化情報/アルトワークス フルコン化 HA22S事例/温度センサ関連 | L38: #温度 #センサ #LINKECU #フルコン化 #アルトワークス #HA22S #K6A #LINKECUセッティング #新規格K6A #温度センサ校正 #センサ校正 | M38: 2000
A39: misc-emanage-191520 | B39: TRUST e-manage オプション 吸気圧力センサ 特性測定結果 | C39: （共通・車種特定なし） | D39: E-manage | E39: フルコンを使用した場合は、センサの特性が分かれば、ほとんどのセンサーが流用使用できます。 | F39: https://note.com/labratory_ktech/n/ndaf171191520 | H39: 2025-03-30 | I39: センサ・計測データ | K39: 吸気圧力センサ 電圧-圧力特性測定結果 | M39: 1000
A40: misc-linkecu-575188 | B40: MC21S K6A ワゴンR 純正ECUピンアサイン エクセルファイル | C40: （共通・車種特定なし） | D40: LINKECU | E40: HA22S後期アルトワークスを事例にフルコン化作業を紹介しています。 | F40: https://note.com/labratory_ktech/n/n522bbf575188 | H40: 2025-03-30 | I40: 配線・ピンアサイン資料 | K40: 新規格 K6A フルコン化情報 | L40: #ダウンロード #配線 #LINKECU #ECUチューニング #フルコン化 #K6A #LINKECUセッティング #新規格K6A #MC21S | M40: 2000
...

Sheet 車種展開_Pivot用
A1: 元slug | B1: 車種 | C1: カテゴリ | D1: ECU | E1: STEP表記 | F1: STEP_L1 | G1: STEP_L2 | H1: STEP_L3 | I1: タイトル | J1: 公開日 | K1: 価格 | L1: マガジン名 | M1: note URL
A2: misc-84a7b3 | B2: （共通・車種特定なし） | C2: その他 | I2: 初めましてなのか、お久しぶりなのか？ | J2: 2025-02-18 | K2: 0 | L2: （未分類） | M2: https://note.com/labratory_ktech/n/nf4258784a7b3
A3: misc-linkecu-e865c2 | B3: （共通・車種特定なし） | C3: 基礎知識・準備 | D3: LINKECU | I3: 自動車 フルコン化に必要なモノ | J3: 2025-02-20 | K3: 0 | L3: ECUフルコン化への道 | M3: https://note.com/labratory_ktech/n/n192a1be865c2
A4: misc-228e07 | B4: （共通・車種特定なし） | C4: 基礎知識・準備 | I4: 安定化電源を使う理由 | J4: 2025-02-23 | K4: 0 | L4: ECUフルコン化への道 | M4: https://note.com/labratory_ktech/n/nfe3377228e07
A5: misc-linkecu-6aecda | B5: （共通・車種特定なし） | C5: 基礎知識・準備 | D5: LINKECU/MaxxECU/MOTEC/EMTRON/Haltech | I5: フルコン勉強にお勧めのECUは？ | J5: 2025-02-24 | K5: 0 | L5: ECUフルコン化への道 | M5: https://note.com/labratory_ktech/n/n9881036aecda
A6: misc-linkecu-160fa8 | B6: （共通・車種特定なし） | C6: 基礎知識・準備 | D6: LINKECU | I6: 燃料セッティング 空燃比計とは？ | J6: 2025-02-26 | K6: 0 | L6: ECUフルコン化への道 | M6: https://note.com/labratory_ktech/n/n182b31160fa8
A7: misc-linkecu-711682 | B7: （共通・車種特定なし） | C7: 基礎知識・準備 | D7: LINKECU/MaxxECU | I7: 初心者？がECUフルコンを選定するのに一番大事なこと | J7: 2025-02-27 | K7: 0 | L7: ECUフルコン化への道 | M7: https://note.com/labratory_ktech/n/n612e8f711682
A8: misc-linkecu-275a47 | B8: （共通・車種特定なし） | C8: 他社ECU・機器情報 | D8: LINKECU/MaxxECU | I8: LINKECU MAXXECU どの機種選べばいいの？ | J8: 2025-03-01 | K8: 0 | L8: LINKECU 関連/MaxxECU フルコン化への道/ECUフルコン化への道 | M8: https://note.com/labratory_ktech/n/n5515d1275a47
A9: esse-cc2978 | B9: エッセ(ESSE) | C9: センサ・計測データ | I9: フルコン化の第１の壁 吸気圧力センサ特性どうやって測定するの？ | J9: 2025-03-02 | K9: 0 | L9: エッセ ESSE LINKECU フルコン化 への道/ECUフルコン化への道/吸気圧力センサ 電圧-圧力特性測定結果 | M9: https://note.com/labratory_ktech/n/n4fe44ccc2978
A10: fd3s-linkecu-774f15 | B10: FD3S(RX-7) | C10: 基礎知識・準備 | D10: LINKECU | I10: LINKECU PLUG IN FD3S 後期 電源供給 | J10: 2025-03-03 | K10: 0 | L10: LINKECU 関連/ECUフルコン化への道/FD3S LINKECU フルコン化への道 | M10: https://note.com/labratory_ktech/n/n4a4ba4774f15
A11: ae86-linkecu-460ba3 | B11: AE86 | C11: センサ・計測データ | D11: LINKECU/MaxxECU | I11: AE86 4AG 吸気圧力センサ特性 品番89421-12020 | J11: 2025-03-03 | K11: 2000 | L11: 吸気圧力センサ 電圧-圧力特性測定結果 | M11: https://note.com/labratory_ktech/n/n3b3112460ba3
A12: misc-linkecu-16c728 | B12: （共通・車種特定なし） | C12: 基礎知識・準備 | D12: LINKECU | I12: LINKECU 通電 と アンロック作業 | J12: 2025-03-03 | K12: 0 | L12: ECUフルコン化への道 | M12: https://note.com/labratory_ktech/n/n4a2c4616c728
A13: misc-8b7628 | B13: （共通・車種特定なし） | C13: センサ・計測データ | I13: AE92 4AG 吸気圧力センサ特性 品番 80420-20300 | J13: 2025-03-04 | K13: 2000 | L13: 吸気圧力センサ 電圧-圧力特性測定結果 | M13: https://note.com/labratory_ktech/n/nee83a58b7628
A14: misc-2b1b60 | B14: （共通・車種特定なし） | C14: 基礎知識・準備 | I14: フルコン化への道 ビギーバック配線とは？ | J14: 2025-03-05 | K14: 0 | L14: ECUフルコン化への道 | M14: https://note.com/labratory_ktech/n/n4a159e2b1b60
A15: altoworks-step0-4670ac | B15: アルトワークス(HA22S/HA23S) | C15: STEP本編（フルコン化手順） | E15: STEP0 | F15: 0 | I15: HA22Sフルコン化 STEP0 ECUピンアサイン | J15: 2025-03-08 | K15: 500 | L15: 新規格 K6A フルコン化情報/アルトワークス フルコン化 HA22S事例 | M15: https://note.com/labratory_ktech/n/na152494670ac
A16: altoworks-linkecu-step1-362693 | B16: アルトワークス(HA22S/HA23S) | C16: STEP本編（フルコン化手順） | D16: LINKECU | E16: STEP1 | F16: 1 | I16: HA22S K6A フルコン化 STEP1 ビギーバックハーネス | J16: 2025-03-08 | K16: 0 | L16: アルトワークス フルコン化 HA22S事例 | M16: https://note.com/labratory_ktech/n/ne2f733362693
A17: altoworks-linkecu-f776fe | B17: アルトワークス(HA22S/HA23S) | C17: 基礎知識・準備（車種別） | D17: LINKECU | I17: HA22S K6A アルトワークスフルコン化 | J17: 2025-03-08 | K17: 0 | L17: アルトワークス フルコン化 HA22S事例 | M17: https://note.com/labratory_ktech/n/n3eb953f776fe
A18: cappuccino-linkecu-e16ea7 | B18: カプチーノ(F6A) | C18: センサ・計測データ | D18: LINKECU | I18: F6A アルトカプチーノ 吸気圧力センサ特性 品番 18590-64D00 | J18: 2025-03-08 | K18: 3000 | L18: 吸気圧力センサ 電圧-圧力特性測定結果 | M18: https://note.com/labratory_ktech/n/neaa561e16ea7
A19: misc-2668a9 | B19: （共通・車種特定なし） | C19: センサ・計測データ | I19: インジェクター燃料圧力制御の基礎 燃料のリターン、リターンレスシステムとは？ | J19: 2025-03-08 | K19: 0 | L19: 燃料、インジェクター関連 無効噴射時間 | M19: https://note.com/labratory_ktech/n/n0f32362668a9
A20: altoworks-linkecu-step2-e48ff8 | B20: アルトワークス(HA22S/HA23S) | C20: STEP本編（フルコン化手順） | D20: LINKECU | E20: STEP2 | F20: 2 | I20: HA22S LINKECU フルコン化 STEP2 電源供給 | J20: 2025-03-09 | K20: 0 | L20: アルトワークス フルコン化 HA22S事例/ECUフルコン化への道 | M20: https://note.com/labratory_ktech/n/n3bb503e48ff8
A21: altoworks-b01abe | B21: アルトワークス(HA22S/HA23S) | C21: 基礎知識・準備 | I21: 温度センサ校正の基礎知識 分圧とは？ | J21: 2025-03-10 | K21: 0 | L21: アルトワークス フルコン化 HA22S事例/ECUフルコン化への道 | M21: https://note.com/labratory_ktech/n/ne58f6db01abe
A22: altoworks-linkecu-step3-ff1549 | B22: アルトワークス(HA22S/HA23S) | C22: STEP本編（フルコン化手順） | D22: LINKECU | E22: STEP3 | F22: 3 | I22: HA22S フルコン化 STEP3 スロットル信号入力とアナログ入力エラー設定の観点 | J22: 2025-03-11 | K22: 100 | L22: アルトワークス フルコン化 HA22S事例/ECUフルコン化への道 | M22: https://note.com/labratory_ktech/n/n58a1cbff1549
A23: altoworks-075bb5 | B23: アルトワークス(HA22S/HA23S) | C23: 部品選定・レビュー | I23: HA22 温度センサー 温度-抵抗特性測定結果 | J23: 2025-03-13 | K23: 500 | L23: アルトワークス フルコン化 HA22S事例/HA22S 部品関連情報/温度センサ関連 | M23: https://note.com/labratory_ktech/n/n6cea0c075bb5
A24: misc-a2b1f2 | B24: （共通・車種特定なし） | C24: センサ・計測データ | I24: 温度センサの温度-抵抗特性 と B定数 | J24: 2025-03-13 | K24: 0 | L24: LINKECU 関連/温度センサ関連/ECUフルコン化への道 | M24: https://note.com/labratory_ktech/n/nf904daa2b1f2
A25: copen-linkecu-6815ae | B25: コペン(L880K) | C25: センサ・計測データ | D25: LINKECU | I25: JB-DET コペン 吸気圧力センサ 品番 89421-97201 特性測定結果 | J25: 2025-03-14 | K25: 2000 | L25: 吸気圧力センサ 電圧-圧力特性測定結果/コペン L880K フルコン化 | M25: https://note.com/labratory_ktech/n/nd325a66815ae
A26: altoworks-linkecu-91bebe | B26: アルトワークス(HA22S/HA23S) | C26: センサ・計測データ | D26: LINKECU | I26: HA22S 吸気圧力センサ HITACHI製 品番 18590-78G50 特性測定結果 | J26: 2025-03-15 | K26: 2000 | L26: アルトワークス フルコン化 HA22S事例/吸気圧力センサ 電圧-圧力特性測定結果 | M26: https://note.com/labratory_ktech/n/n6cfee691bebe
A27: altoworks-linkecu-step4-ceb9fa | B27: アルトワークス(HA22S/HA23S) | C27: STEP本編（フルコン化手順） | D27: LINKECU | E27: STEP4 | F27: 4 | I27: HA22S フルコン化 STEP4 吸気圧力信号入力 と センサCaliblation設定の観点 | J27: 2025-03-16 | K27: 0 | L27: アルトワークス フルコン化 HA22S事例/ECUフルコン化への道 | M27: https://note.com/labratory_ktech/n/nb5f07fceb9fa
A28: altoworks-linkecu-b980ee | B28: アルトワークス(HA22S/HA23S) | C28: その他 | D28: LINKECU | I28: HA23 吸気圧力センサ Denso製 品番 18590-79F00 特性測定結果 | J28: 2025-03-16 | K28: 2000 | L28: （未分類） | M28: https://note.com/labratory_ktech/n/n0c63cbb980ee
A29: misc-26b3d3 | B29: （共通・車種特定なし） | C29: センサ・計測データ | I29: 燃料圧力と噴射量の関係性 | J29: 2025-03-17 | K29: 0 | L29: 燃料、インジェクター関連 無効噴射時間/ECUフルコン化への道 | M29: https://note.com/labratory_ktech/n/n57277926b3d3
A30: misc-bb3fb4 | B30: （共通・車種特定なし） | C30: センサ・計測データ | I30: インジェクタ流量と馬力の関係 | J30: 2025-03-18 | K30: 200 | L30: 燃料、インジェクター関連 無効噴射時間/ECUフルコン化への道 | M30: https://note.com/labratory_ktech/n/n5809cebb3fb4
A31: misc-linkecu-922d25 | B31: （共通・車種特定なし） | C31: 配線・ピンアサイン資料 | D31: LINKECU | I31: TA-HE21S ラパンSS 純正ECUピンアサイン エクセルファイル | J31: 2025-03-19 | K31: 5000 | L31: 新規格 K6A フルコン化情報 | M31: https://note.com/labratory_ktech/n/n959df6922d25
A32: misc-6a1297 | B32: （共通・車種特定なし） | C32: センサ・計測データ | I32: HN12等 F6A ターボ 吸気圧力センサ Denso製 品番 18590-76G50 特性測定結果 | J32: 2025-03-21 | K32: 2000 | L32: 吸気圧力センサ 電圧-圧力特性測定結果 | M32: https://note.com/labratory_ktech/n/n3cf1366a1297
A33: misc-motec-4c23e9 | B33: （共通・車種特定なし） | C33: センサ・計測データ | D33: MOTEC | I33: GM MAP SENSOR | J33: 2025-03-21 | K33: 0 | L33: 吸気圧力センサ 電圧-圧力特性測定結果 | M33: https://note.com/labratory_ktech/n/n966de44c23e9
A34: misc-linkecu-733713 | B34: （共通・車種特定なし） | C34: センサ・計測データ | D34: LINKECU | I34: 温度センサ校正の基礎 LINKECU例 プルアップ抵抗 有り編 | J34: 2025-03-23 | K34: 0 | L34: LINKECU 関連/温度センサ関連 | M34: https://note.com/labratory_ktech/n/n8e1736733713
A35: misc-linkecu-451883 | B35: （共通・車種特定なし） | C35: センサ・計測データ | D35: LINKECU | I35: 温度センサ校正の基礎 LINKECU例 プルアップ抵抗OFF ビギーバック編 | J35: 2025-03-25 | K35: 500 | L35: LINKECU 関連/温度センサ関連/ECUフルコン化への道 | M35: https://note.com/labratory_ktech/n/n0085d3451883
A36: misc-linkecu-1d2d43 | B36: （共通・車種特定なし） | C36: 部品選定・レビュー | D36: LINKECU | I36: SARD1000cc/min 低抵抗 インジェクター | J36: 2025-03-27 | K36: 0 | L36: 車関係部品 写真置き場 | M36: https://note.com/labratory_ktech/n/nfb525f1d2d43
A37: misc-linkecu-660efd | B37: （共通・車種特定なし） | C37: センサ・計測データ | D37: LINKECU | I37: 1JZ 2JZ 等 ターボ用 吸気圧力センサ Denso製 品番 89421-12111 特性測定結果 | J37: 2025-03-29 | K37: 2000 | L37: 吸気圧力センサ 電圧-圧力特性測定結果 | M37: https://note.com/labratory_ktech/n/n9b53de660efd
A38: altoworks-linkecu-step5-e41aba | B38: アルトワークス(HA22S/HA23S) | C38: STEP本編（フルコン化手順） | D38: LINKECU | E38: STEP5 | F38: 5 | I38: HA22S フルコン化 STEP5 温度センサ校正設定 | J38: 2025-03-29 | K38: 2000 | L38: 新規格 K6A フルコン化情報/アルトワークス フルコン化 HA22S事例/温度センサ関連 | M38: https://note.com/labratory_ktech/n/ne1c5b4e41aba
A39: misc-emanage-191520 | B39: （共通・車種特定なし） | C39: センサ・計測データ | D39: E-manage | I39: TRUST e-manage オプション 吸気圧力センサ 特性測定結果 | J39: 2025-03-30 | K39: 1000 | L39: 吸気圧力センサ 電圧-圧力特性測定結果 | M39: https://note.com/labratory_ktech/n/ndaf171191520
A40: misc-linkecu-575188 | B40: （共通・車種特定なし） | C40: 配線・ピンアサイン資料 | D40: LINKECU | I40: MC21S K6A ワゴンR 純正ECUピンアサイン エクセルファイル | J40: 2025-03-30 | K40: 2000 | L40: 新規格 K6A フルコン化情報 | M40: https://note.com/labratory_ktech/n/n522bbf575188
...

Sheet 車種×カテゴリ集計
A1: 車種＼カテゴリ | B1: STEP本編（フルコン化手順） | C1: 基礎知識・準備 | D1: 基礎知識・準備（車種別） | E1: 部品選定・レビュー | F1: センサ・計測データ | G1: CAN通信・周辺機器連携 | H1: 配線・ピンアサイン資料 | I1: 他社ECU・機器情報 | J1: まとめ・振り返り | K1: 電子工作・自作ツール | L1: その他 | M1: 合計
A2: アルトワークス(HA22S/HA23S) | B2: =COUNTIFS(車種展開_Pivot用!$B$2:$B$320,$A2,車種展開_Pivot用!$C$2:$C$320,B$1) | C2: =COUNTIFS(車種展開_Pivot用!$B$2:$B$320,$A2,車種展開_Pivot用!$C$2:$C$320,C$1) | D2: =COUNTIFS(車種展開_Pivot用!$B$2:$B$320,$A2,車種展開_Pivot用!$C$2:$C$320,D$1) | E2: =COUNTIFS(車種展開_Pivot用!$B$2:$B$320,$A2,車種展開_Pivot用!$C$2:$C$320,E$1) | F2: =COUNTIFS(車種展開_Pivot用!$B$2:$B$320,$A2,車種展開_Pivot用!$C$2:$C$320,F$1) | G2: =COUNTIFS(車種展開_Pivot用!$B$2:$B$320,$A2,車種展開_Pivot用!$C$2:$C$320,G$1) | H2: =COUNTIFS(車種展開_Pivot用!$B$2:$B$320,$A2,車種展開_Pivot用!$C$2:$C$320,H$1) | I2: =COUNTIFS(車種展開_Pivot用!$B$2:$B$320,$A2,車種展開_Pivot用!$C$2:$C$320,I$1) | ... L2: =COUNTIFS(車種展開_Pivot用!$B$2:$B$320,$A2,車種展開_Pivot用!$C$2:$C$320,L$1) | M2: =SUM(B2:L2)
A3: ソニカ(SONICA) | B3: =COUNTIFS(車種展開_Pivot用!$B$2:$B$320,$A3,車種展開_Pivot用!$C$2:$C$320,B$1) | C3: =COUNTIFS(車種展開_Pivot用!$B$2:$B$320,$A3,車種展開_Pivot用!$C$2:$C$320,C$1) | D3: =COUNTIFS(車種展開_Pivot用!$B$2:$B$320,$A3,車種展開_Pivot用!$C$2:$C$320,D$1) | E3: =COUNTIFS(車種展開_Pivot用!$B$2:$B$320,$A3,車種展開_Pivot用!$C$2:$C$320,E$1) | F3: =COUNTIFS(車種展開_Pivot用!$B$2:$B$320,$A3,車種展開_Pivot用!$C$2:$C$320,F$1) | G3: =COUNTIFS(車種展開_Pivot用!$B$2:$B$320,$A3,車種展開_Pivot用!$C$2:$C$320,G$1) | H3: =COUNTIFS(車種展開_Pivot用!$B$2:$B$320,$A3,車種展開_Pivot用!$C$2:$C$320,H$1) | I3: =COUNTIFS(車種展開_Pivot用!$B$2:$B$320,$A3,車種展開_Pivot用!$C$2:$C$320,I$1) | ... L3: =COUNTIFS(車種展開_Pivot用!$B$2:$B$320,$A3,車種展開_Pivot用!$C$2:$C$320,L$1) | M3: =SUM(B3:L3)
A4: エッセ(ESSE) | B4: =COUNTIFS(車種展開_Pivot用!$B$2:$B$320,$A4,車種展開_Pivot用!$C$2:$C$320,B$1) | C4: =COUNTIFS(車種展開_Pivot用!$B$2:$B$320,$A4,車種展開_Pivot用!$C$2:$C$320,C$1) | D4: =COUNTIFS(車種展開_Pivot用!$B$2:$B$320,$A4,車種展開_Pivot用!$C$2:$C$320,D$1) | E4: =COUNTIFS(車種展開_Pivot用!$B$2:$B$320,$A4,車種展開_Pivot用!$C$2:$C$320,E$1) | F4: =COUNTIFS(車種展開_Pivot用!$B$2:$B$320,$A4,車種展開_Pivot用!$C$2:$C$320,F$1) | G4: =COUNTIFS(車種展開_Pivot用!$B$2:$B$320,$A4,車種展開_Pivot用!$C$2:$C$320,G$1) | H4: =COUNTIFS(車種展開_Pivot用!$B$2:$B$320,$A4,車種展開_Pivot用!$C$2:$C$320,H$1) | I4: =COUNTIFS(車種展開_Pivot用!$B$2:$B$320,$A4,車種展開_Pivot用!$C$2:$C$320,I$1) | ... L4: =COUNTIFS(車種展開_Pivot用!$B$2:$B$320,$A4,車種展開_Pivot用!$C$2:$C$320,L$1) | M4: =SUM(B4:L4)
A5: ロードスター(NB8/NB1) | B5: =COUNTIFS(車種展開_Pivot用!$B$2:$B$320,$A5,車種展開_Pivot用!$C$2:$C$320,B$1) | C5: =COUNTIFS(車種展開_Pivot用!$B$2:$B$320,$A5,車種展開_Pivot用!$C$2:$C$320,C$1) | D5: =COUNTIFS(車種展開_Pivot用!$B$2:$B$320,$A5,車種展開_Pivot用!$C$2:$C$320,D$1) | E5: =COUNTIFS(車種展開_Pivot用!$B$2:$B$320,$A5,車種展開_Pivot用!$C$2:$C$320,E$1) | F5: =COUNTIFS(車種展開_Pivot用!$B$2:$B$320,$A5,車種展開_Pivot用!$C$2:$C$320,F$1) | G5: =COUNTIFS(車種展開_Pivot用!$B$2:$B$320,$A5,車種展開_Pivot用!$C$2:$C$320,G$1) | H5: =COUNTIFS(車種展開_Pivot用!$B$2:$B$320,$A5,車種展開_Pivot用!$C$2:$C$320,H$1) | I5: =COUNTIFS(車種展開_Pivot用!$B$2:$B$320,$A5,車種展開_Pivot用!$C$2:$C$320,I$1) | ... L5: =COUNTIFS(車種展開_Pivot用!$B$2:$B$320,$A5,車種展開_Pivot用!$C$2:$C$320,L$1) | M5: =SUM(B5:L5)
A6: FD3S(RX-7) | B6: =COUNTIFS(車種展開_Pivot用!$B$2:$B$320,$A6,車種展開_Pivot用!$C$2:$C$320,B$1) | C6: =COUNTIFS(車種展開_Pivot用!$B$2:$B$320,$A6,車種展開_Pivot用!$C$2:$C$320,C$1) | D6: =COUNTIFS(車種展開_Pivot用!$B$2:$B$320,$A6,車種展開_Pivot用!$C$2:$C$320,D$1) | E6: =COUNTIFS(車種展開_Pivot用!$B$2:$B$320,$A6,車種展開_Pivot用!$C$2:$C$320,E$1) | F6: =COUNTIFS(車種展開_Pivot用!$B$2:$B$320,$A6,車種展開_Pivot用!$C$2:$C$320,F$1) | G6: =COUNTIFS(車種展開_Pivot用!$B$2:$B$320,$A6,車種展開_Pivot用!$C$2:$C$320,G$1) | H6: =COUNTIFS(車種展開_Pivot用!$B$2:$B$320,$A6,車種展開_Pivot用!$C$2:$C$320,H$1) | I6: =COUNTIFS(車種展開_Pivot用!$B$2:$B$320,$A6,車種展開_Pivot用!$C$2:$C$320,I$1) | ... L6: =COUNTIFS(車種展開_Pivot用!$B$2:$B$320,$A6,車種展開_Pivot用!$C$2:$C$320,L$1) | M6: =SUM(B6:L6)
A7: カプチーノ(F6A) | B7: =COUNTIFS(車種展開_Pivot用!$B$2:$B$320,$A7,車種展開_Pivot用!$C$2:$C$320,B$1) | C7: =COUNTIFS(車種展開_Pivot用!$B$2:$B$320,$A7,車種展開_Pivot用!$C$2:$C$320,C$1) | D7: =COUNTIFS(車種展開_Pivot用!$B$2:$B$320,$A7,車種展開_Pivot用!$C$2:$C$320,D$1) | E7: =COUNTIFS(車種展開_Pivot用!$B$2:$B$320,$A7,車種展開_Pivot用!$C$2:$C$320,E$1) | F7: =COUNTIFS(車種展開_Pivot用!$B$2:$B$320,$A7,車種展開_Pivot用!$C$2:$C$320,F$1) | G7: =COUNTIFS(車種展開_Pivot用!$B$2:$B$320,$A7,車種展開_Pivot用!$C$2:$C$320,G$1) | H7: =COUNTIFS(車種展開_Pivot用!$B$2:$B$320,$A7,車種展開_Pivot用!$C$2:$C$320,H$1) | I7: =COUNTIFS(車種展開_Pivot用!$B$2:$B$320,$A7,車種展開_Pivot用!$C$2:$C$320,I$1) | ... L7: =COUNTIFS(車種展開_Pivot用!$B$2:$B$320,$A7,車種展開_Pivot用!$C$2:$C$320,L$1) | M7: =SUM(B7:L7)
A8: Porsche996 | B8: =COUNTIFS(車種展開_Pivot用!$B$2:$B$320,$A8,車種展開_Pivot用!$C$2:$C$320,B$1) | C8: =COUNTIFS(車種展開_Pivot用!$B$2:$B$320,$A8,車種展開_Pivot用!$C$2:$C$320,C$1) | D8: =COUNTIFS(車種展開_Pivot用!$B$2:$B$320,$A8,車種展開_Pivot用!$C$2:$C$320,D$1) | E8: =COUNTIFS(車種展開_Pivot用!$B$2:$B$320,$A8,車種展開_Pivot用!$C$2:$C$320,E$1) | F8: =COUNTIFS(車種展開_Pivot用!$B$2:$B$320,$A8,車種展開_Pivot用!$C$2:$C$320,F$1) | G8: =COUNTIFS(車種展開_Pivot用!$B$2:$B$320,$A8,車種展開_Pivot用!$C$2:$C$320,G$1) | H8: =COUNTIFS(車種展開_Pivot用!$B$2:$B$320,$A8,車種展開_Pivot用!$C$2:$C$320,H$1) | I8: =COUNTIFS(車種展開_Pivot用!$B$2:$B$320,$A8,車種展開_Pivot用!$C$2:$C$320,I$1) | ... L8: =COUNTIFS(車種展開_Pivot用!$B$2:$B$320,$A8,車種展開_Pivot用!$C$2:$C$320,L$1) | M8: =SUM(B8:L8)
A9: AE86 | B9: =COUNTIFS(車種展開_Pivot用!$B$2:$B$320,$A9,車種展開_Pivot用!$C$2:$C$320,B$1) | C9: =COUNTIFS(車種展開_Pivot用!$B$2:$B$320,$A9,車種展開_Pivot用!$C$2:$C$320,C$1) | D9: =COUNTIFS(車種展開_Pivot用!$B$2:$B$320,$A9,車種展開_Pivot用!$C$2:$C$320,D$1) | E9: =COUNTIFS(車種展開_Pivot用!$B$2:$B$320,$A9,車種展開_Pivot用!$C$2:$C$320,E$1) | F9: =COUNTIFS(車種展開_Pivot用!$B$2:$B$320,$A9,車種展開_Pivot用!$C$2:$C$320,F$1) | G9: =COUNTIFS(車種展開_Pivot用!$B$2:$B$320,$A9,車種展開_Pivot用!$C$2:$C$320,G$1) | H9: =COUNTIFS(車種展開_Pivot用!$B$2:$B$320,$A9,車種展開_Pivot用!$C$2:$C$320,H$1) | I9: =COUNTIFS(車種展開_Pivot用!$B$2:$B$320,$A9,車種展開_Pivot用!$C$2:$C$320,I$1) | ... L9: =COUNTIFS(車種展開_Pivot用!$B$2:$B$320,$A9,車種展開_Pivot用!$C$2:$C$320,L$1) | M9: =SUM(B9:L9)
A10: コペン(L880K) | B10: =COUNTIFS(車種展開_Pivot用!$B$2:$B$320,$A10,車種展開_Pivot用!$C$2:$C$320,B$1) | C10: =COUNTIFS(車種展開_Pivot用!$B$2:$B$320,$A10,車種展開_Pivot用!$C$2:$C$320,C$1) | D10: =COUNTIFS(車種展開_Pivot用!$B$2:$B$320,$A10,車種展開_Pivot用!$C$2:$C$320,D$1) | E10: =COUNTIFS(車種展開_Pivot用!$B$2:$B$320,$A10,車種展開_Pivot用!$C$2:$C$320,E$1) | F10: =COUNTIFS(車種展開_Pivot用!$B$2:$B$320,$A10,車種展開_Pivot用!$C$2:$C$320,F$1) | G10: =COUNTIFS(車種展開_Pivot用!$B$2:$B$320,$A10,車種展開_Pivot用!$C$2:$C$320,G$1) | H10: =COUNTIFS(車種展開_Pivot用!$B$2:$B$320,$A10,車種展開_Pivot用!$C$2:$C$320,H$1) | I10: =COUNTIFS(車種展開_Pivot用!$B$2:$B$320,$A10,車種展開_Pivot用!$C$2:$C$320,I$1) | ... L10: =COUNTIFS(車種展開_Pivot用!$B$2:$B$320,$A10,車種展開_Pivot用!$C$2:$C$320,L$1) | M10: =SUM(B10:L10)
A11: ケータハムスーパー7(620R) | B11: =COUNTIFS(車種展開_Pivot用!$B$2:$B$320,$A11,車種展開_Pivot用!$C$2:$C$320,B$1) | C11: =COUNTIFS(車種展開_Pivot用!$B$2:$B$320,$A11,車種展開_Pivot用!$C$2:$C$320,C$1) | D11: =COUNTIFS(車種展開_Pivot用!$B$2:$B$320,$A11,車種展開_Pivot用!$C$2:$C$320,D$1) | E11: =COUNTIFS(車種展開_Pivot用!$B$2:$B$320,$A11,車種展開_Pivot用!$C$2:$C$320,E$1) | F11: =COUNTIFS(車種展開_Pivot用!$B$2:$B$320,$A11,車種展開_Pivot用!$C$2:$C$320,F$1) | G11: =COUNTIFS(車種展開_Pivot用!$B$2:$B$320,$A11,車種展開_Pivot用!$C$2:$C$320,G$1) | H11: =COUNTIFS(車種展開_Pivot用!$B$2:$B$320,$A11,車種展開_Pivot用!$C$2:$C$320,H$1) | I11: =COUNTIFS(車種展開_Pivot用!$B$2:$B$320,$A11,車種展開_Pivot用!$C$2:$C$320,I$1) | ... L11: =COUNTIFS(車種展開_Pivot用!$B$2:$B$320,$A11,車種展開_Pivot用!$C$2:$C$320,L$1) | M11: =SUM(B11:L11)
A12: S2000 | B12: =COUNTIFS(車種展開_Pivot用!$B$2:$B$320,$A12,車種展開_Pivot用!$C$2:$C$320,B$1) | C12: =COUNTIFS(車種展開_Pivot用!$B$2:$B$320,$A12,車種展開_Pivot用!$C$2:$C$320,C$1) | D12: =COUNTIFS(車種展開_Pivot用!$B$2:$B$320,$A12,車種展開_Pivot用!$C$2:$C$320,D$1) | E12: =COUNTIFS(車種展開_Pivot用!$B$2:$B$320,$A12,車種展開_Pivot用!$C$2:$C$320,E$1) | F12: =COUNTIFS(車種展開_Pivot用!$B$2:$B$320,$A12,車種展開_Pivot用!$C$2:$C$320,F$1) | G12: =COUNTIFS(車種展開_Pivot用!$B$2:$B$320,$A12,車種展開_Pivot用!$C$2:$C$320,G$1) | H12: =COUNTIFS(車種展開_Pivot用!$B$2:$B$320,$A12,車種展開_Pivot用!$C$2:$C$320,H$1) | I12: =COUNTIFS(車種展開_Pivot用!$B$2:$B$320,$A12,車種展開_Pivot用!$C$2:$C$320,I$1) | ... L12: =COUNTIFS(車種展開_Pivot用!$B$2:$B$320,$A12,車種展開_Pivot用!$C$2:$C$320,L$1) | M12: =SUM(B12:L12)
A13: NSX | B13: =COUNTIFS(車種展開_Pivot用!$B$2:$B$320,$A13,車種展開_Pivot用!$C$2:$C$320,B$1) | C13: =COUNTIFS(車種展開_Pivot用!$B$2:$B$320,$A13,車種展開_Pivot用!$C$2:$C$320,C$1) | D13: =COUNTIFS(車種展開_Pivot用!$B$2:$B$320,$A13,車種展開_Pivot用!$C$2:$C$320,D$1) | E13: =COUNTIFS(車種展開_Pivot用!$B$2:$B$320,$A13,車種展開_Pivot用!$C$2:$C$320,E$1) | F13: =COUNTIFS(車種展開_Pivot用!$B$2:$B$320,$A13,車種展開_Pivot用!$C$2:$C$320,F$1) | G13: =COUNTIFS(車種展開_Pivot用!$B$2:$B$320,$A13,車種展開_Pivot用!$C$2:$C$320,G$1) | H13: =COUNTIFS(車種展開_Pivot用!$B$2:$B$320,$A13,車種展開_Pivot用!$C$2:$C$320,H$1) | I13: =COUNTIFS(車種展開_Pivot用!$B$2:$B$320,$A13,車種展開_Pivot用!$C$2:$C$320,I$1) | ... L13: =COUNTIFS(車種展開_Pivot用!$B$2:$B$320,$A13,車種展開_Pivot用!$C$2:$C$320,L$1) | M13: =SUM(B13:L13)
A14: （共通・車種特定なし） | B14: =COUNTIFS(車種展開_Pivot用!$B$2:$B$320,$A14,車種展開_Pivot用!$C$2:$C$320,B$1) | C14: =COUNTIFS(車種展開_Pivot用!$B$2:$B$320,$A14,車種展開_Pivot用!$C$2:$C$320,C$1) | D14: =COUNTIFS(車種展開_Pivot用!$B$2:$B$320,$A14,車種展開_Pivot用!$C$2:$C$320,D$1) | E14: =COUNTIFS(車種展開_Pivot用!$B$2:$B$320,$A14,車種展開_Pivot用!$C$2:$C$320,E$1) | F14: =COUNTIFS(車種展開_Pivot用!$B$2:$B$320,$A14,車種展開_Pivot用!$C$2:$C$320,F$1) | G14: =COUNTIFS(車種展開_Pivot用!$B$2:$B$320,$A14,車種展開_Pivot用!$C$2:$C$320,G$1) | H14: =COUNTIFS(車種展開_Pivot用!$B$2:$B$320,$A14,車種展開_Pivot用!$C$2:$C$320,H$1) | I14: =COUNTIFS(車種展開_Pivot用!$B$2:$B$320,$A14,車種展開_Pivot用!$C$2:$C$320,I$1) | ... L14: =COUNTIFS(車種展開_Pivot用!$B$2:$B$320,$A14,車種展開_Pivot用!$C$2:$C$320,L$1) | M14: =SUM(B14:L14)
A15: 合計 | B15: =SUM(B2:B14) | C15: =SUM(C2:C14) | D15: =SUM(D2:D14) | E15: =SUM(E2:E14) | F15: =SUM(F2:F14) | G15: =SUM(G2:G14) | H15: =SUM(H2:H14) | I15: =SUM(I2:I14) | ... M15: =SUM(M2:M14)

Sheet フルコン化ツリー
A1: 階層 | B1: STEP/順序 | C1: タイトル | D1: ECU | E1: 公開日 | F1: 価格 | G1: マガジン名 | H1: note URL
A2: ■ アルトワークス(HA22S/HA23S) | B2: 82件
A3: ◆ STEP本編（フルコン化手順） | B3: 51件
A4: ・ | B4: STEP0 | C4: HA22Sフルコン化 STEP0 ECUピンアサイン | E4: 2025-03-08 | F4: 500 | G4: 新規格 K6A フルコン化情報/アルトワークス フルコン化 HA22S事例 | H4: https://note.com/labratory_ktech/n/na152494670ac
A5: ・ | B5: STEP1 | C5: HA22S K6A フルコン化 STEP1 ビギーバックハーネス | D5: LINKECU | E5: 2025-03-08 | F5: 0 | G5: アルトワークス フルコン化 HA22S事例 | H5: https://note.com/labratory_ktech/n/ne2f733362693
A6: ・ | B6: STEP2 | C6: HA22S LINKECU フルコン化 STEP2 電源供給 | D6: LINKECU | E6: 2025-03-09 | F6: 0 | G6: アルトワークス フルコン化 HA22S事例/ECUフルコン化への道 | H6: https://note.com/labratory_ktech/n/n3bb503e48ff8
A7: ・ | B7: STEP3 | C7: HA22S フルコン化 STEP3 スロットル信号入力とアナログ入力エラー設定の観点 | D7: LINKECU | E7: 2025-03-11 | F7: 100 | G7: アルトワークス フルコン化 HA22S事例/ECUフルコン化への道 | H7: https://note.com/labratory_ktech/n/n58a1cbff1549
A8: ・ | B8: STEP4 | C8: HA22S フルコン化 STEP4 吸気圧力信号入力 と センサCaliblation設定の観点 | D8: LINKECU | E8: 2025-03-16 | F8: 0 | G8: アルトワークス フルコン化 HA22S事例/ECUフルコン化への道 | H8: https://note.com/labratory_ktech/n/nb5f07fceb9fa
A9: ・ | B9: STEP5 | C9: HA22S フルコン化 STEP5 温度センサ校正設定 | D9: LINKECU | E9: 2025-03-29 | F9: 2000 | G9: 新規格 K6A フルコン化情報/アルトワークス フルコン化 HA22S事例/温度センサ関連 | H9: https://note.com/labratory_ktech/n/ne1c5b4e41aba
A10: ・ | B10: STEP5-2 | C10: HA22S K6A フルコン化 STEP5-2 吸気温度センサ 高速度応答化の勧め 吸気温度の“遅れ”がパワーを落としているかも？ | E10: 2025-12-12 | F10: 200 | G10: アルトワークス フルコン化 HA22S事例/LINKECU 関連/パーツレビュー/温度センサ関連/ECUフルコン化への道 | H10: https://note.com/labratory_ktech/n/n204b41865d7b
A11: ・ | B11: STEP5-3 | C11: HA22S LINKECU フルコン化 STEP5-3 スタンドアローン化 温度入力 プルアップON編 | D11: LINKECU | E11: 2025-12-11 | F11: 100 | G11: アルトワークス フルコン化 HA22S事例/LINKECU 関連 | H11: https://note.com/labratory_ktech/n/nbcfdc30b2924
A12: ・ | B12: STEP6 | C12: HA22S フルコン化 STEP6 回転数トリガ設定 | D12: LINKECU | E12: 2025-03-30 | F12: 100 | G12: アルトワークス フルコン化 HA22S事例/ECUフルコン化への道 | H12: https://note.com/labratory_ktech/n/nb50b3a888601
A13: ・ | B13: STEP7 | C13: HA22S フルコン化 STEP7 エンジン設定 | D13: LINKECU | E13: 2025-04-02 | F13: 0 | G13: 新規格 K6A フルコン化情報/アルトワークス フルコン化 HA22S事例 | H13: https://note.com/labratory_ktech/n/n051d663a2b38
A14: ・ | B14: STEP8 | C14: HA22S フルコン化 STEP8 点火テスト | D14: LINKECU | E14: 2025-04-22 | F14: 0 | G14: アルトワークス フルコン化 HA22S事例 | H14: https://note.com/labratory_ktech/n/n2c4e23a28e89
A15: ・ | B15: STEP9 | C15: HA22S フルコン化 STEP9 点火基準合わせ | D15: LINKECU | E15: 2025-05-03 | F15: 500 | G15: アルトワークス フルコン化 HA22S事例/ECUフルコン化への道 | H15: https://note.com/labratory_ktech/n/n0042b76e88d5
A16: ・ | B16: STEP10 | C16: HA22S LINKECU フルコン化 STEP10 車速入力 | D16: LINKECU | E16: 2025-05-21 | F16: 100 | G16: 新規格 K6A フルコン化情報/アルトワークス フルコン化 HA22S事例 | H16: https://note.com/labratory_ktech/n/na48afe8958ff
A17: ・ | B17: STEP10-2 | C17: HA22S LINKECU フルコン スタンドアローン化 STEP10-2 車速信号線スタンドアロン入力 | D17: LINKECU | E17: 2025-12-08 | F17: 100 | G17: アルトワークス フルコン化 HA22S事例 | H17: https://note.com/labratory_ktech/n/n9c7cac38153c
A18: ・ | B18: STEP11 | C18: HA22S LINKECU フルコン化 STEP11 ギヤ認識 | D18: LINKECU | E18: 2025-05-23 | F18: 200 | G18: アルトワークス フルコン化 HA22S事例/ECUフルコン化への道 | H18: https://note.com/labratory_ktech/n/n072b717d733e
A19: ・ | B19: STEP12 | C19: HA22S LINKECU フルコン化 STEP12 デジタルインプット 電気負荷信号入力 | D19: LINKECU | E19: 2025-06-04 | F19: 100 | G19: アルトワークス フルコン化 HA22S事例 | H19: https://note.com/labratory_ktech/n/n7c61e01cdbb0
A20: ・ | B20: STEP13 | C20: HA22S LINKECU フルコン化 STEP13 デジタルインプット ブロアファン信号入力 | D20: LINKECU | E20: 2025-06-07 | F20: 100 | G20: アルトワークス フルコン化 HA22S事例 | H20: https://note.com/labratory_ktech/n/n21ee0a0eae4c
A21: ・ | B21: STEP14 | C21: HA22S LINKECU フルコン化 STEP14 デジタルインプット エアコンリクエスト信号入力 | D21: LINKECU | E21: 2025-06-09 | F21: 100 | G21: アルトワークス フルコン化 HA22S事例 | H21: https://note.com/labratory_ktech/n/n23416a4613b9
A22: ・ | B22: STEP14-2 | C22: HA22S LINKECU フルコン化 STEP14-2 エアコンクラッチOUTPUT 置き換え | D22: LINKECU | E22: 2025-09-27 | F22: 200 | G22: 新規格 K6A フルコン化情報/アルトワークス フルコン化 HA22S事例 | H22: https://note.com/labratory_ktech/n/nee94b9551b76
... A54: ・ | B54: STEP31 | C54: HA22S LINKECU フルコン スタンドアローン化 STEP31 センサ電源５V出力置き換え | D54: LINKECU | E54: 2025-12-08 | F54: 0 | G54: アルトワークス フルコン化 HA22S事例 | H54: https://note.com/labratory_ktech/n/nc7caf9cf0e95
A55: ◆ 基礎知識・準備 | B55: 9件
A56: ・ | B56: 2025-03-10 | C56: 温度センサ校正の基礎知識 分圧とは？ | E56: 2025-03-10 | F56: 0 | G56: アルトワークス フルコン化 HA22S事例/ECUフルコン化への道 | H56: https://note.com/labratory_ktech/n/ne58f6db01abe
A57: ・ | B57: 2025-06-01 | C57: スイッチ入力の基礎 Hisideインプット Losideインプット プルアップ抵抗 プルダウン抵抗 | D57: LINKECU | E57: 2025-06-01 | F57: 500 | G57: アルトワークス フルコン化 HA22S事例/ECUフルコン化への道 | H57: https://note.com/labratory_ktech/n/nc8a5ba6e5875
A58: ・ | B58: 2025-07-17 | C58: LINKECU フルコン化 CEライト設定 LINKがエンジンチェックランプ を点灯する条件は？ | D58: LINKECU | E58: 2025-07-17 | F58: 0 | G58: アルトワークス フルコン化 HA22S事例/LINKECU 関連 | H58: https://note.com/labratory_ktech/n/n33600240af5a
A59: ・ | B59: 2025-07-20 | C59: LINKECU フルコン化 LINKECUの エンジンチェックランプを消すには？ ボタンを付けないでフォルトをクリアする設定方法も紹介！ | D59: LINKECU | E59: 2025-07-20 | F59: 500 | G59: アルトワークス フルコン化 HA22S事例/LINKECU 関連 | H59: https://note.com/labratory_ktech/n/n1aa7874de3ad
A60: ・ | B60: 2025-07-29 | C60: LINKECU フルコン化 ノック Knock 振幅ゲイン調整 | D60: LINKECU | E60: 2025-07-29 | F60: 500 | G60: アルトワークス フルコン化 HA22S事例/LINKECU 関連 | H60: https://note.com/labratory_ktech/n/nad82cb347b90
A61: ・ | B61: 2025-08-09 | C61: LINKECU フルコン化 ノック Knock 気筒毎 Gain調整 気筒補正 | D61: LINKECU | E61: 2025-08-09 | F61: 400 | G61: 新規格 K6A フルコン化情報/アルトワークス フルコン化 HA22S事例/LINKECU 関連 | H61: https://note.com/labratory_ktech/n/nee136e77b006
A62: ・ | B62: 2025-08-16 | C62: LINKECU フルコン化 ノック リタード設定 と Knock igntion Trim MAP | D62: LINKECU | E62: 2025-08-16 | F62: 400 | G62: アルトワークス フルコン化 HA22S事例/LINKECU 関連 | H62: https://note.com/labratory_ktech/n/n22460f8dfcd3
A63: ・ | B63: 2026-02-03 | C63: HA22S LINKECUフルコン化 各STEP | D63: LINKECU | E63: 2026-02-03 | F63: 0 | G63: 新規格 K6A フルコン化情報/アルトワークス フルコン化 HA22S事例/ECUフルコン化への道 | H63: https://note.com/labratory_ktech/n/n6100bb08eea1
A64: ・ | B64: 2026-09-09 | C64: LINKECUで インタークーラー ウォータースプレー ポンプ を制御する HA22S トップマウントＩＣ事例 と ECU設定観点 | D64: LINKECU | E64: 2026-09-09 | F64: 300 | G64: 新規格 K6A フルコン化情報/アルトワークス フルコン化 HA22S事例/LINKECU 関連 | H64: https://note.com/labratory_ktech/n/na74a95906e2e
A65: ◆ 基礎知識・準備（車種別） | B65: 4件
A66: ・ | B66: 2025-03-08 | C66: HA22S K6A アルトワークスフルコン化 | D66: LINKECU | E66: 2025-03-08 | F66: 0 | G66: アルトワークス フルコン化 HA22S事例 | H66: https://note.com/labratory_ktech/n/n3eb953f776fe
A67: ・ | B67: 2025-08-03 | C67: LINKECU フルコン化 ノック Knock LIMIT（閾値）設定 ブースト領域編 | D67: LINKECU/MaxxECU | E67: 2025-08-03 | F67: 300 | G67: アルトワークス フルコン化 HA22S事例 | H67: https://note.com/labratory_ktech/n/ne12a279f64a8
A68: ・ | B68: 2025-08-07 | C68: 新規格K6A LINKECU フルコン化 ビギーバック 点火制御置き換え時のアイドルアップ対策 ラパン KEI等 | D68: LINKECU | E68: 2025-08-07 | F68: 1000 | G68: 新規格 K6A フルコン化情報/アルトワークス フルコン化 HA22S事例 | H68: https://note.com/labratory_ktech/n/n19445cb0e53d
A69: ・ | B69: 2025-12-09 | C69: HA22S LINKECU フルコン スタンドアローン化 アナログ入力 デジタル入力 ビギーバック配線撤去 設定変更なし編 | D69: LINKECU | E69: 2025-12-09 | F69: 0 | G69: アルトワークス フルコン化 HA22S事例 | H69: https://note.com/labratory_ktech/n/nae42f2e73fc3
A70: ◆ 部品選定・レビュー | B70: 11件
A71: ・ | B71: 2025-03-13 | C71: HA22 温度センサー 温度-抵抗特性測定結果 | E71: 2025-03-13 | F71: 500 | G71: アルトワークス フルコン化 HA22S事例/HA22S 部品関連情報/温度センサ関連 | H71: https://note.com/labratory_ktech/n/n6cea0c075bb5
...
